# 28. 오류처리

대부분의 프로그래밍 언어는 프로그램에서 발생하는 오류에 대비하기 위해 오류를 처리하는 기능을 제공한다. 스위프트도 오류를 적절히 처리할 수 있는 기능을 제공한다. 스위프트가 제공하는 오류처리 기능에 대해 알아보자.

## 28.1 오류처리란

**오류처리** 는 프로그램이 오류를 일으켰을 때 이것을 감지하고 회복시키는 일련의 과정이다.

프로그램에서 모든 기능이 우리가 원하는대로 100% 정확히 동작한다는 보장은 없다. 특히나 전달받아야 하는 값이 까다롭거나 데이터를 가공하는 데 소비하는 자원이 많을 경우 오류가 발생할 확률이 높아진다. 이런 가능성이 있는 기능을 구현할 때는 오류가 발생할 수 있음을 항상 고려해야 한다.

예를 들어 디스크의 파일을 읽어오는 기능을 생각해보자. 파일이 존재하지 않을 수도 있으며, 읽기 권한이 없을 수도 있고, 잘못된 파일일 가능성도 있다. 이렇게 파일을 읽어오는 간단한 기능에서도 오류가 발생할 수 있는 가능성이 여럿 존재한다. 오류처리 기능을 통해 이런 상황들을 구별하여 프로그램 자체적으로 오류를 해결할 수 있고, 사용자와 상호작용을 통해 오류를 어떤 방향으로 풀어나갈지 제어할 수도 있다.

다만 주의할 점은 스위프트의 오류처리 기능을 통해 시스템(예를 들어 운영체제 등 우리가 작성하는 응용프로그램 외부)에서 발생한 오류를 처리할 수 있는 것이 아님을 명시해야 한다.

## 28.2 오류의 표현

스위프트에서 오류는 Error라는 프로토콜을 준수하는 타입의 값을 통해 표현된다. Error 프로토콜은 사실상 요구사항이 없는 빈 프로토콜일 뿐이지만, 오류를 표현하기 위한 타입(주로 열거형)은 이 프로토콜을 채택한다.

스위프트의 열거형은 오류의 종류를 나타내기에 아주 적합한 기능이다. 연관 값을 통해 오류에 관한 부가 정보를 제공할 수도 있다. 다음 코드는 프로그램 내에서 자판기를 작동시키려고 할 때 발생하는 오류의 종류를 열거형으로 표현한 것이다.

```swift
enum VendingMachineError: Error {
    case invalidSelection
    case insufficientFunds(coinsNeeded: Int)
    case outOfStock
}
```

VendingMachineError 열거형을 살펴보면 Error 프로토콜을 채택함으로써 오류처리를 위한 타입임을 알 수 있다. 그리고 이 코드에서 오류의 종류는 invalidSelection(유효하지 않은 선택), insufficientFunds(coinsNeeded: Int) (자금 부족 - 필요한 동전 개수), outOfStock(품절) 등 세 가지가 있다. 이처럼 열거형을 통해 오류의 종류를 표현하는 것이 가장 일반적이며 편리한 방법이다.

이렇게 오류의 종류를 미리 예상한 다음, 오류 때문에 다음에 행할 동작이 정상적으로 진행되지 않을 때라면 **오류를 던져** 주면 된다. 오류를 던져줄 때는 throw 구문을 사용한다. 만약 자금이 부족하고 동전이 5개 더 필요한 상황이라면 throw VendingMachineError.insufficientFunds(coinsNeeded: 5) 라고 오류를 던져줄 수 있다.

이제 던져진 오류를 포착하고 처리하는 방법을 알아보자.

## 28.3 오류 포착 및 처리

오류를 던질 수도 있지만 오류가 던져지는 것에 대비하여 던져진 오류를 처리하기 위한 코드도 작성해야 한다. 예를 들어 던져진 오류가 무엇인지 판단하여 다시 문제를 해결한다든지, 다른 방법으로 문제 해결을 시도해 본다든지, 오류를 알리고 사용자에게 선택 권한을 넘겨주어 다음에 어떤 동작을 하게 할 것인지 결정하도록 유도하는 등의 코드를 작성해야 한다.

스위프트에는 오류를 처리하기 위한 네 가지 방법이 있다.

* 함수에서 발생한 오류를 해당 함수를 호출한 코드에 알리는 방법
* do-catch 구문을 이용하여 오류를 처리하는 방법
* 옵셔널 값으로 오류를 처리하는 방법
* 오류가 발생하지 않을 것이라고 확신하는 방법

각각의 방법에 대해 알아보도록 하겠다.

### 28.3.1 함수에서 발생한 오류 알리기

먼저 함수에서 발생한 오류를 해당 암수를 호출한 코드에 알리는 방법이다. 함수가 오류를 던지면 프로그램의 흐름이 바뀔 가능성이 매우 크다. 그러므로 어디서 오류를 던지고 받을 것인가 결정하는 것은 매우 중요하다. try 키워드로 던져진 오류를 받을 수 있다. try 키워드는 try 또는 try?, try! 등으로 표현할 수 있다.

함수, 메서드, 이니셜라이저의 매개변수 뒤에 throws 키워드를 사용하면 해당 함수, 메서드, 이니셜라이저는 오류를 던질 수 있다. 일반적으로 func cannotThrowErrors() -> String 처럼 표현하던 것에 func cannotThrowErrors() throws -> String 처럼 throws 키워드를 명시해주면 오류를 던질 수 있다. 이런 함수는 호출했을 때, 동작 도중 오류가 발생하면 자신을 호출한 코드에 오류를 던져서 오류를 알릴 수 있다.

**TIP**. throws는 함수나 메서드 자체에 타입에도 영향을 미친다. 즉, throws 함수나 메서드는 같은 이름의 throws가 명시되지 않는 함수나 메서드와 구분된다. 또, throws를 포함한 함수, 메서드, 이니셜라이저는 일반 함수, 메서드, 이니셜라이저로 재정의할 수 없다. 반대로 일반 함수, 메서드, 이니셜라이저는 throws 함수, 메서드, 이니셜라이저로 재정의할 수 있다.

```swift
enum VendingMachineError: Error {
    case invalidSelection
    case insfficientFunds(coinsNeeded: Int)
    case outOfStock
}

struct Item {
    var price: Int
    var count: Int
}

class VendingMachine {
    var inventory = [
        "Candy Bar": Item(price: 12, count: 7),
        "Chips": Item(price: 10, count: 4),
        "Biscuit": Item(price: 7, count: 11)
    ]

    var coinsDeposited = 0

    func dispense(snack: String) {
        print("\(snack) 제공")
    }

    func vend(itemNamed name: String) throws {
        guard let item = self.inventory[name] else {
            throw VendingMachineError.invalidSelection
        }

        guard item.count > 0 else {
            throw VendingMachineError.outOfStock
        }

        guard item.price <= self.coinsDeposited else {
            throw VendingMachineError.insfficientFunds(
                coinsNeeded: item.price - self.coinsDeposited)
        }

        self.coinsDeposited -= item.price

        var newItem = item
        newItem.count -= 1
        self.inventory[name] = newItem

        self.dispense(snack: name)
    }
}

let favoriteSnacks = [
    "yagom": "Chips",
    "jinsung": "Biscuit",
    "heejin": "Chocolate"
]

func buyFavoriteSnack(person: String, vendingMachine: VendingMachine) throws {
    let snackName = favoriteSnacks[person] ?? "Candy Bar"
    try vendingMachine.vend(itemNamed: snackName)
}

struct PurchaseSnack {
    let name: String
    init(name: String, vendingMachine: VendingMachine) throws {
        try vendingMachine.vend(itemNamed: name)
        self.name = name
    }
}

let machine: VendingMachine = VendingMachine()
machine.coinsDeposited = 30

var purchase: PurchaseSnack = try PurchaseSnack(name: "Biscuit", vendingMachine: machine)
// Biscuit 제공

print(purchase.name)        // Biscuit

for (person, favoriteSnack) in favoriteSnacks {
    print(person, favoriteSnack)
    try buyFavoriteSnack(person: person, vendingMachine: machine)
}
// Biscuit 제공
// Biscuit
// yagom Chips
// Chips 제공
// jinsumg Biscuit
// heejin Chocolate

// 오류 발생!!
```

위의 자판기 VendingMachine 클래스는 오류를 던질 수 있는 vend(itemNamed:) 메서드가 있다. vend(itemNamed:) 메서드 내부에서는 오류가 발생했을 때 흐름을 제어하기 위해 guard를 통한 빠른 종료 구문을 사용한다. 특정 조건이 충족되지 않는담녀 throws 키워드를 통해 오류를 던져서 오류가 발생했다는 것을 자신을 호출한 코드에 알린다.

또한 vend(itemNamed:) 메서드가 오류를 던질 가능성이 있으므로, vend(itemNamed:) 메서드를 호출하는 함수 또한 오류를 던질 수 있어야 한다. 그래서 buyFavoriteSnack(person:vendingMachine:) 함수도 throws 키워드를 통해 오류를 던질 수 있는 함수로 구현해주어야 한다.

오류를 던질 수 있는 함수, 메서드, 이니셜라이저를 호출하는 코드는 반드시 오류를 처리할 수 있는 구문을 작성해주어야 한다. 그러나 위 코드에는 오류가 발생할 수 있는 메서드와 함수를 호출하면서도 try로 시도만 할 뿐 오류가 발생했을 때 처리할 수 있는 코드는 작성되어 있지 않는다. 위 코드는 for-in 구문 내에서 buyFavoriteSnack(person:vendingMachine:)함수 호출 중 오류가 발생한 후 적절한 처리를 해주지 않았기 때문에 다음 코드가 정상적으로 동작하지 않을 것이다.

이렇게 발생한 오류는 자신을 호출한 코드로 던져서 알릴 수는 있지만, 오류를 받은 코드가 적절히 오류를 처리해주지 않는다면 이후의 코드는 작동하지 않는다. 던져진 오류를 처리하는 방법에 대해 알아보겠다.

### 28.3.2 do-catch 구문을 이용하여 오류처리

다음은 do-catch 구문을 이용하여 오류를 처리하는 방법이다. 함수, 메서드, 이니셜라이저 등에서 오류를 던져주면 오류 발생을 전달받은 코드 블록은 do-catch 구문을 사용하여 오류를 처리해주어야 한다. do 절 내부의 코드에서 오류를 던지면 catch 절에서 오류를 전달받아 적절이 처리해주면 된다.

do-catch 구문은 보통 다음처럼 표현한다.

```swift
do {
    try 오류 발생 가능코드
    오류가 발생하지 않으면 실행할 코드
} catch 오류 패턴 1 {
    처리 코드
} catch 오류 패턴 2 where 추가 조건 {
    처리 코드
}
```

catch 절에서는 catch 키워드 뒤에 처리할 오류의 종류를 써준다. 만약 catch 뒤에 오류의 종류를 명시하지 않고 코드 블록을 생성하면 블록 내부에 암시적으로 error라는 이름의 지역상수가 오류의 내용으로 들어온다.

```swift
func buyFavoriteSnack(person: String, vendingMachine: VendingMachine) {
    let snackName = favoriteSnacks[person] ?? "Candy Bar"
    tryingVend(itemNamed: snackName, vendingMachine: vendingMachine)
}

struct PurchaseSnack {
    let name: String
    init(name: String, vendingMachine: VendingMachine) {
        tryingVend(itemNamed: name, vendingMachine: vendingMachine)
        self.name = name
    }
}

func tryingVend(itemNamed: String, vendingMachine: VendingMachine) {
    do {
        try vendingMachine.vend(itemNamed: itemNamed)
    } catch VendingMachineError.invalidSelection {
        print("유효하지 않은 선택")
    } catch VendingMachineError.outOfStock {
        print("품절")
    } catch VendingMachineError.insfficientFunds(let coinsNeeded) {
        print("자금 부족 - 동전 \(coinsNeeded)개를 추가로 지급해주세요.")
    } catch {
        print("그 외 오류 발생 : ", error)
    }
}

let machine: VendingMachine = VendingMachine()
machine.coinsDeposited = 20

var purchase: PurchaseSnack = PurchaseSnack(name: "Biscuit", vendingMachine: machine)
// Biscuit 제공

print(purchase.name)        // Biscuit

purchase = PurchaseSnack(name: "Ice Cream", vendingMachine: machine)
// 유효하지 않은 선택

print(purchase.name)        // Ice Cream

for (person, favoriteSnack) in favoriteSnacks {
    print(person, favoriteSnack)
    try buyFavoriteSnack(person: person, vendingMachine: machine)
}

// yagom Chips
// Chips 제공
// heejin Chocolate
// 유효하지 않은 선택
// jinsung Biscuit
// 자금 부족 - 동전 4개를 추가로 지급해주세요.
```

위 코드는 do-catch 구문을 사용하여 처리하는 함수를 별도로 만들어주었다. 그에 따라 오류를 받아서 다시 던지던 함수들이 더 이상 다른 곳으로 오류를 던지지 않아도 되는 형태가 되엇다. 더불어 오류를 적절히 처리해주자 코드가 중간에 중단되지 않고 끝까지 정상 동작하는 것을 볼 수 있다.

### 28.3.3 옵셔널 값으로 오류처리

try?를 사용하여 옵셔널 값으로 변환하여 오류를 처리할 수도 있다. try? 표현을 통해 동작하던 코드가 오류를 던지면 그 코드의 반환 값은 nil이 된다.

```swift
func someThrowingFunction(shouldThrowError: Bool) throws -> Int {
    if shouldThrowError {
        enum SomeError: Error {
            case justSomeError
        }

        throw SomeError.justSomeError
    }

    return 100
}

let x: Optional = try? someThrowingFunction(shouldThrowError: true)
print(x)    // nil

let y: Optional = try? someThrowingFunction(shouldThrowError: false)
print(y)    // Optional(100)
```

위 코드를 보면 try? 표현을 사용하여 호출한 함수가 오류를 던지면 반환 값이 nil로 반환되고, 오류가 발생하지 않으면 옵셔널 값으로 반환되는 것을 확인할 수 있다. 이렇게 do-catch 구문을 사용하지 않더라도 옵셔널을 사용하여 오류를 처리할 수도 있다. 여기서 주목할 점은 someThrowingFunction(shouldThrowError:)의 반환타입이 Int라도 try? 표현을 사용하면 반환 타입이 옵셔널이 된다는 점이다.

우리가 기존에 반환 타입으로 옵셔널을 활용하던 방법과 결합하여 사용할 수도 있다.

```swift
func fetchData() -> Data? {
    if let data = try? fetchDataFromDisk() {
        return data
    }
    if let data = try? fetchDataFromServer() {
        return data
    }
    return nil
}
```

위 코드의 fetchData() 함수는 반환 타입을 옵셔널로 정의했다. 즉, 함수 내부에서 제대로 처리가 이루어지지 않으면 반환 값이 nil이 될 수 있음을 내포하는 것이다. 예를 들어 데이터를 디스크에서 가져오지 못하면 서버에서 가져오는 것을 시도해보고 그조차 없으면 nil을 반환해주도록 응용해볼 수 있다.

### 28.3.4 오류가 발생하지 않을 것이라고 확신하는 방법

오류를 처리하는 마지막 방법으로는 오류가 발생하지 않을 것이라는 확신을 갖고 처리하는 방법이다. 코드를 작성하는 프로그래머가 오류를 던질 수 있는 함수 등을 호출할 때 오류가 절대로 발생하지 않을 것이라고 확신할 수 있는 상황이라면 오류가 발생하지 않을 것이라는 전제하에 try! 표현을 사용할 수 있다. 이 표현은 다른 느낌표 표현(암시적 추출 옵셔널, 강제 타입캐스팅 등)과 마찬가지로 실제 오류가 발생하면 런타임 오류가 발생하여 프로그램이 강제 종료된다.

```swift
func someThrowingFunction(shouldThrowError: Bool) throws -> Int {
    if shouldThrowError {
        enum SomeError: Error {
            case justSomeError
        }

        throw SomeError.justSomeError
    }

    return 100
}

let y: Int = try! someThrowingFunction(shouldThrowError: false)
print(y)    // 100

let x: Int = try! someThrowingFunction(shouldThrowError: true) // 런타임 오류 !!
```

### 28.3.5 다시 던지기

함수나 메서드는 rethrows 키워드를 사용하여 자신의 매개변수로 전달받은 함수가 오류를 던진다는 것을 나타낼 수 있다. rethrows 키워드를 사용하여 **다시 던지기**가 가능하게 하려면 최소 하나 이상의 오류 발생 가능한 함수를 매개변수로 전달받아야 한다. 다음 코드를 통해 오류를 다시 던지는 함수의 모습을 살펴보자

```swift
// 오류를 던지는 함수
func someThrowingFunction() throws {
    enum SomeError: Error {
        case justSomeError
    }

    throw SomeError.justSomeError
}

// 다시 던지기 함수
func someFunction(callback: () throws -> Void) rethrows {
    try callback()  // 다시 던지기 함수는 오류를 다시 던질 뿐 따로 처리하지는 않는다.
}

do {
    try someFunction(callback: someThrowingFunction)
} catch {
    print(error)
}
// justSomeError
```

다시 던지기 함수 또는 메서드는 기본적으로 스스로 오류를 던지지 못한다. 즉, 자신 내부에 직접적으로 throw 구문을 사용할 수 없다. 그러나 catch 절 내부에서는 throw 구문을 작성할 수 있다. 다시 던지기 함수나 메서드가 오류를 던지는 함수를 do-catch 구문 내부에서 호출하고 catch 절 내부에서 다른 오류를 던짐으로써 오류를 던지는 함수에서 발생한 오류를 제어할 수 있다. 다시 던지기 내부의 catch 절에서는 다시 던지기 함수의 매개변수로 전달받은 오류던지기 함수만 호출하고 결과로 던져진 오류만 제어할 수 있다. 다음 코드를 통해 알아보자.

```swift
// 오류를 던지는 함수
func someThrowingFunction() throws {
    enum SomeError: Error {
        case justSomeError
    }

    throw SomeError.justSomeError
}

// 다시 던지기 함수
func someFunction(callback: () throws -> Void) rethrows {
    enum AnotherError: Error {
        case justAnotherError
    }

    do {
        // 매개변수로 전달한 오류 던지기 함수이므로
        // catch 절에서 제어할 수 있다.
        try callback()
    } catch {
        throw AnotherError.justAnotherError
    }

    do {
        // 매개변수로 전달한 오류 던지기 함수가 아니므로
        // catch 절에서 제어할 수 없다.
        try someThrowingFunction()
    } catch {
        // 오류 발생!
        throw AnotherError.justAnotherError
    }

    // catch 절 외부에서 단독으로 오류를 던질 수 없다. 오류발생 !
}
```

부모클래스의 다시 던지기 메서드(rethrows 메서드)는 자식클래스에서 던지기 메서드(throws 메서드)로 재정의할 수 없다. 그러나 부모클래스의 던지기 메서드는 자식클래스에서 다시 던지기 메서드로 재정의할 수 있다.

그리고 만약 프로토콜 요구사항 중에서 다시 던지기 메서드가 있다면, 던지기 메서드를 구현한다고 해서 요구사항을 충족시킬 수는 없다. 그러나 프로토콜 요구사항 중에 던지기 메서드가 있다면 다시 던지기 메서드를 구현해서 요구사항을 충족시킬 수 있다. 다음 코드를 통해 이를 알아보자.

```swift
protocol SomeProtocol {
    func someThrowingFunctionFromProtocol(callback: () throws -> Void) throws
    func someRethrowingFunctionFromProtocol(callback: () throws -> Void) rethrows
}

class SomeClass: SomeProtocol {
    func someThrowingFunction(callback: () throws -> Void) throws {     }
    func someFunction(callback: () throws -> Void) rethrows {     }

    // 던지기 메서드는 다시 던지기 메서드를 요구하는 프로토콜을 충족할 수 없다.
    // 오류 발생
    func someRethrowingFunctionFromProtocol(callback: () throws -> Void) throws {    }

    // 다시 던지기 메서드는 던지기 메서드를 요구하는 프로토콜의 요구사항에 부합하다.
    func someThrowingFunctionFromProtocol(callback: () throws -> Void) rethrows {    }

}

class SomeChildClass: SomeClass {
    // 부모클래스의 던지기 메서드는 자식클래스에서 다시 던지기 메서드로 재정의할 수 있다.
    override func someThrowingFunction(callback: () throws -> Void) rethrows {    }

    // 부모클래스의 다시 던지기 메서드는 자식클래스에서 던지기 메서드로 재정의할 수 없다.
    // 오류 발생!
    override func someFunction(callback: () throws -> Void) throws {    }
}
```

위 코드의 SomeProtocol 에서 요구한 던지기 함수 someThrowingFunctionFromProtocol(callback:)과 다시 던지기 함수 someRethrowingFunctionFromProtocol(callback:)을 다시 각각 다시 던지기 함수와 던지기 함수로 구현해보았다. 던지기 메서드는 다시 던지기 메서드의 요구에 부합하지만 다시 던지기 메서드는 던지기 메서드 요구에 부합하지 못함을 확인할 수 있다. 또, 부모클래스의 던지기 메서드는 자식클래스에서 다시 던지기 메서드로 재정의할 수 있는 반면, 부모클래스의 다시 던지기 메서드는 자식클래스의 던지기 메서드로 재정의할 수 없음을 확인할 수 있다.

### 28.3.6 후처리 defer

defer 구문을 사용하여 현재 코드 블록을 나가기 전에 꼭 실행해야 하는 코드를 작성해줄 수 있다. 즉, defer 구문은 코드가 블록을 어떤 식으로 빠져나가든 간에 꼭 실행해야 하는 마무리 작업을 할 수 있도록 도와준다. 그 말인즉슨, 오류가 발생하여 코드 블록을 빠져나가는것이든, 정상적으로 코드가 블록을 빠져나가는 것이든 간에 defer 구문은 코드가 블록을 빠져나가기 전에 무조건 실행되는 것을 보장한다는 뜻이다.

예를 들어 함수 내에서 파일을 열어 사용하다가 오류가 발생하여 코드가 블록을 빠져나가더라도 파일을 정상적으로 닫아 메모리에서 해제해야 하기 때문에 defer 구문 내부에는 파일을 닫는 코드를 작성해주어 정상적으로 파일이 메모리에서 해제될 수 있도록 해야한다.

**NOTE_** defer 구문과 오류처리

defer 구문은 꼭 오류처리 상황에서만 사용해야 하는 것은 아니지만, 오류처리를 할 때 유용하게 쓰이기에 오류처리 파트에서 소개한다. defer **구문은 오류처리 상황뿐만 아니라 함수, 메서드, 반복문, 조건문 등등 보통의 코드 블록 어디에서든 사용할 수 있다.**

```swift
for i in 0...2 {
    defer {
        print("A", terminator: " ")
    }
    print(i, terminator: " ")

    if i % 2 == 0 {
        defer {
            print("", terminator: "\n")
        }

        print("It's even", terminator: " ")
    }
}
// 0 It's even
// A 1 A 2 It's even
// A
```

```swift
func writeData() {
    let file = openFile()

    // 함수 코드 블록을 빠져나가기 직전 무조건 실행되어 파일을 잊지 않고 닫아줌
    defer {
        closeFile()
    }

    if ... {
        return
    }

    if ... {
        return
    }

    // 처리 끝
}
```

만약 defer 구문이 없었다면 다음 코드와 같이 중복된 코드가 많아질 것이고 차후 유지관리가 어려울뿐더러 코드가 길어지다보면 프로그래머가 파일닫기 코드를 닫지 않는 실수를 할 가능성도 높아진다.

```swift
func writeData() {
    let file = openFile()

    if ... {
        closeFile()
        return
    }

    if ... {
        closeFile()
        return
    }

    closeFile()

    // 처리 끝
}
```

defer 구문은 현재 코드 범위를 벗어나기 전까지 실행을 미루고있다가 프로그램 실행 흐름이 코드 범위를 벗어나기 직전 실행된다. defer 구문 내부에는 break, return 등과 같이 구분을 빠져나갈 수 있는 코드 또는 오류를 던지는 코드는 작성하면 안 된다. 여러 개의 defer 구문이 하나의 범위(블록) 내부에 속해 있다면 맨 마지막에 작성된 구문부터 역순으로 실행된다.

```swift
func someThrowingFunction(shouldThrowErrer: Bool) throws -> Int {
    defer {
        print("First")
    }

    if shouldThrowErrer {
        enum SomeError: Error {
            case justSomeError
        }

        throw SomeError.justSomeError
    }

    defer {
        print("Second")
    }

    defer {
        print("Third")
    }

    return 100
}

try? someThrowingFunction(shouldThrowErrer: true)
// First
// 오류를 던지기 직전까지 작성된 defer 구문까지만 실행된다.

try? someThrowingFunction(shouldThrowErrer: false)
// Third
// Second
// First
```

그런데, do 구문을 catch 절과 함께 사용하지 않고 단독으로 사용할 수도 있다. 코드 블록 내부에 또 한 단계 하위의 블록을 만들고자 할 때입니다. 이럴 때는 하위 블록이 종료될 때 그 내부의 defer 구문이 실행된다. 다음 코드에서 defer 구문이 여러 개 존재할 때 어떤 순서로 실행되는지 확인해보자. 맨 아래 주석으로 나와있는 결과를 보지 않고 어떤 순서로 진행될지 예상해보자!

```swift
func someFunction() {
    print("1")

    defer {
        print("2")
    }

    do {
        defer {
            print("3")
        }
        print("4")
    }

    defer {
        print("5")
    }

    print("6")
}

someFunction()

// 1
// 4
// 3
// 6
// 5
// 2
```

이처럼 스위프트는 오류를 처리하는 다양한 방법을 제공하며, 다른 기능과도 멋지게 조합하여 사용할 수 있다. 스위프트 표준 라이브러리의 함수나 메서드 등에도 throws와 rethrows 키워드가 종종 발견된다. 언제, 어떻게 오류를 던져줄지 잘 생각해보면 스위프트에 대한 이해도도 높아질 것이다. 또한 스위프트 표준 라이브러리를 보며, 스위프트를 만든 사람들이 언제 이 키워드를 사용했는지를 이해한다면 언제 이 키워드를 사용해야 할지 금방 슥듭할 것이다. 이 장을 익히고 자신의 코드에서 throws와 rethrows 키워드를 적재적소에 적용해보자.
